ERROR:utils.file_processor:Error processing Google Slides: [Errno 2] No such file or directory: 'path/to/credentials.json'
Traceback (most recent call last):
  File "/home/runner/SlideCheckAI/utils/file_processor.py", line 80, in process_google_slides
    creds = Credentials.from_authorized_user_file(os.environ.get('GOOGLE_CREDENTIALS_PATH', 'path/to/credentials.json'))
            ^^^^^^^^^^^^^^^^^^^^^^^^^^^^^^^^^^^^^^^^^^^^^^^^^^^^^^^^^^^^^^^^^^^^^^^^^^^^^^^^^^^^^^^^^^^^^^^^^^^^^^^^^^^^
  File "/home/runner/SlideCheckAI/.pythonlibs/lib/python3.11/site-packages/google/oauth2/credentials.py", line 515, in from_authorized_user_file
    with io.open(filename, "r", encoding="utf-8") as json_file:
         ^^^^^^^^^^^^^^^^^^^^^^^^^^^^^^^^^^^^^^^^
FileNotFoundError: [Errno 2] No such file or directory: 'path/to/credentials.json'
ERROR:utils.file_processor:Error in process_file: [Errno 2] No such file or directory: 'path/to/credentials.json'
Traceback (most recent call last):
  File "/home/runner/SlideCheckAI/utils/file_processor.py", line 21, in process_file
    return process_url(input_data)
           ^^^^^^^^^^^^^^^^^^^^^^^
  File "/home/runner/SlideCheckAI/utils/file_processor.py", line 49, in process_url
    return process_google_slides(url)
           ^^^^^^^^^^^^^^^^^^^^^^^^^^
  File "/home/runner/SlideCheckAI/utils/file_processor.py", line 80, in process_google_slides
    creds = Credentials.from_authorized_user_file(os.environ.get('GOOGLE_CREDENTIALS_PATH', 'path/to/credentials.json'))
            ^^^^^^^^^^^^^^^^^^^^^^^^^^^^^^^^^^^^^^^^^^^^^^^^^^^^^^^^^^^^^^^^^^^^^^^^^^^^^^^^^^^^^^^^^^^^^^^^^^^^^^^^^^^^
  File "/home/runner/SlideCheckAI/.pythonlibs/lib/python3.11/site-packages/google/oauth2/credentials.py", line 515, in from_authorized_user_file
    with io.open(filename, "r", encoding="utf-8") as json_file:
         ^^^^^^^^^^^^^^^^^^^^^^^^^^^^^^^^^^^^^^^^
FileNotFoundError: [Errno 2] No such file or directory: 'path/to/credentials.json'
ERROR:app:Error during processing: [Errno 2] No such file or directory: 'path/to/credentials.json'
Traceback (most recent call last):
  File "/home/runner/SlideCheckAI/app.py", line 71, in index
    slide_data = process_file(form.url.data)
                 ^^^^^^^^^^^^^^^^^^^^^^^^^^^
  File "/home/runner/SlideCheckAI/utils/file_processor.py", line 21, in process_file
    return process_url(input_data)
           ^^^^^^^^^^^^^^^^^^^^^^^
  File "/home/runner/SlideCheckAI/utils/file_processor.py", line 49, in process_url
    return process_google_slides(url)
           ^^^^^^^^^^^^^^^^^^^^^^^^^^
  File "/home/runner/SlideCheckAI/utils/file_processor.py", line 80, in process_google_slides
    creds = Credentials.from_authorized_user_file(os.environ.get('GOOGLE_CREDENTIALS_PATH', 'path/to/credentials.json'))
            ^^^^^^^^^^^^^^^^^^^^^^^^^^^^^^^^^^^^^^^^^^^^^^^^^^^^^^^^^^^^^^^^^^^^^^^^^^^^^^^^^^^^^^^^^^^^^^^^^^^^^^^^^^^^
  File "/home/runner/SlideCheckAI/.pythonlibs/lib/python3.11/site-packages/google/oauth2/credentials.py", line 515, in from_authorized_user_file
    with io.open(filename, "r", encoding="utf-8") as json_file:
         ^^^^^^^^^^^^^^^^^^^^^^^^^^^^^^^^^^^^^^^^
FileNotFoundError: [Errno 2] No such file or directory: 'path/to/credentials.json'
INFO:werkzeug:172.31.196.27 - - [26/Sep/2024 22:01:30] "POST / HTTP/1.1" 500 -
