DEBUG:utils.file_processor:Starting to process input: /tmp/tmpbrdpjcyj.pdf
PDF processing test passed successfully!
PPTX test skipped: No sample file available
OTP test skipped: No sample file available
DEBUG:asyncio:Using selector: EpollSelector
/home/runner/SlideCheckAI/.pythonlibs/lib/python3.11/site-packages/playwright/driver/node: /lib/x86_64-linux-gnu/libc.so.6: version `GLIBC_2.38' not found (required by /nix/store/r0lvxcdpachvilzmy1w7pnwxikbvm7az-cpplibs/lib/libstdc++.so.6)
/home/runner/SlideCheckAI/.pythonlibs/lib/python3.11/site-packages/playwright/driver/node: /lib/x86_64-linux-gnu/libc.so.6: version `GLIBC_2.33' not found (required by /nix/store/r0lvxcdpachvilzmy1w7pnwxikbvm7az-cpplibs/lib/libstdc++.so.6)
/home/runner/SlideCheckAI/.pythonlibs/lib/python3.11/site-packages/playwright/driver/node: /lib/x86_64-linux-gnu/libc.so.6: version `GLIBC_2.32' not found (required by /nix/store/r0lvxcdpachvilzmy1w7pnwxikbvm7az-cpplibs/lib/libstdc++.so.6)
/home/runner/SlideCheckAI/.pythonlibs/lib/python3.11/site-packages/playwright/driver/node: /lib/x86_64-linux-gnu/libc.so.6: version `GLIBC_2.36' not found (required by /nix/store/r0lvxcdpachvilzmy1w7pnwxikbvm7az-cpplibs/lib/libstdc++.so.6)
/home/runner/SlideCheckAI/.pythonlibs/lib/python3.11/site-packages/playwright/driver/node: /lib/x86_64-linux-gnu/libc.so.6: version `GLIBC_2.34' not found (required by /nix/store/r0lvxcdpachvilzmy1w7pnwxikbvm7az-cpplibs/lib/libstdc++.so.6)
ERROR:utils.file_processor:Error in Playwright (attempt 1): 'PlaywrightContextManager' object has no attribute '_playwright'
DEBUG:asyncio:Using selector: EpollSelector
/home/runner/SlideCheckAI/.pythonlibs/lib/python3.11/site-packages/playwright/driver/node: /lib/x86_64-linux-gnu/libc.so.6: version `GLIBC_2.38' not found (required by /nix/store/r0lvxcdpachvilzmy1w7pnwxikbvm7az-cpplibs/lib/libstdc++.so.6)
/home/runner/SlideCheckAI/.pythonlibs/lib/python3.11/site-packages/playwright/driver/node: /lib/x86_64-linux-gnu/libc.so.6: version `GLIBC_2.33' not found (required by /nix/store/r0lvxcdpachvilzmy1w7pnwxikbvm7az-cpplibs/lib/libstdc++.so.6)
/home/runner/SlideCheckAI/.pythonlibs/lib/python3.11/site-packages/playwright/driver/node: /lib/x86_64-linux-gnu/libc.so.6: version `GLIBC_2.32' not found (required by /nix/store/r0lvxcdpachvilzmy1w7pnwxikbvm7az-cpplibs/lib/libstdc++.so.6)
/home/runner/SlideCheckAI/.pythonlibs/lib/python3.11/site-packages/playwright/driver/node: /lib/x86_64-linux-gnu/libc.so.6: version `GLIBC_2.36' not found (required by /nix/store/r0lvxcdpachvilzmy1w7pnwxikbvm7az-cpplibs/lib/libstdc++.so.6)
/home/runner/SlideCheckAI/.pythonlibs/lib/python3.11/site-packages/playwright/driver/node: /lib/x86_64-linux-gnu/libc.so.6: version `GLIBC_2.34' not found (required by /nix/store/r0lvxcdpachvilzmy1w7pnwxikbvm7az-cpplibs/lib/libstdc++.so.6)
ERROR:utils.file_processor:Error in Playwright (attempt 2): 'PlaywrightContextManager' object has no attribute '_playwright'
DEBUG:asyncio:Using selector: EpollSelector
/home/runner/SlideCheckAI/.pythonlibs/lib/python3.11/site-packages/playwright/driver/node: /lib/x86_64-linux-gnu/libc.so.6: version `GLIBC_2.38' not found (required by /nix/store/r0lvxcdpachvilzmy1w7pnwxikbvm7az-cpplibs/lib/libstdc++.so.6)
/home/runner/SlideCheckAI/.pythonlibs/lib/python3.11/site-packages/playwright/driver/node: /lib/x86_64-linux-gnu/libc.so.6: version `GLIBC_2.33' not found (required by /nix/store/r0lvxcdpachvilzmy1w7pnwxikbvm7az-cpplibs/lib/libstdc++.so.6)
/home/runner/SlideCheckAI/.pythonlibs/lib/python3.11/site-packages/playwright/driver/node: /lib/x86_64-linux-gnu/libc.so.6: version `GLIBC_2.32' not found (required by /nix/store/r0lvxcdpachvilzmy1w7pnwxikbvm7az-cpplibs/lib/libstdc++.so.6)
/home/runner/SlideCheckAI/.pythonlibs/lib/python3.11/site-packages/playwright/driver/node: /lib/x86_64-linux-gnu/libc.so.6: version `GLIBC_2.36' not found (required by /nix/store/r0lvxcdpachvilzmy1w7pnwxikbvm7az-cpplibs/lib/libstdc++.so.6)
/home/runner/SlideCheckAI/.pythonlibs/lib/python3.11/site-packages/playwright/driver/node: /lib/x86_64-linux-gnu/libc.so.6: version `GLIBC_2.34' not found (required by /nix/store/r0lvxcdpachvilzmy1w7pnwxikbvm7az-cpplibs/lib/libstdc++.so.6)
ERROR:utils.file_processor:Error in Playwright (attempt 3): 'PlaywrightContextManager' object has no attribute '_playwright'
ERROR:utils.file_processor:Error processing Canva link: 'PlaywrightContextManager' object has no attribute '_playwright'
Traceback (most recent call last):
  File "/home/runner/SlideCheckAI/utils/file_processor.py", line 160, in process_canva_link
    with sync_playwright() as p:
  File "/home/runner/SlideCheckAI/.pythonlibs/lib/python3.11/site-packages/playwright/sync_api/_context_manager.py", line 79, in __enter__
    playwright = self._playwright
                 ^^^^^^^^^^^^^^^^
AttributeError: 'PlaywrightContextManager' object has no attribute '_playwright'
ERROR:asyncio:Task exception was never retrieved
future: <Task finished name='Task-6' coro=<Connection.run.<locals>.init() done, defined at /home/runner/SlideCheckAI/.pythonlibs/lib/python3.11/site-packages/playwright/_impl/_connection.py:269> exception=Exception('Connection.init: Connection closed while reading from the driver')>
Traceback (most recent call last):
  File "/home/runner/SlideCheckAI/.pythonlibs/lib/python3.11/site-packages/playwright/_impl/_connection.py", line 270, in init
    self.playwright_future.set_result(await self._root_object.initialize())
                                      ^^^^^^^^^^^^^^^^^^^^^^^^^^^^^^^^^^^^
  File "/home/runner/SlideCheckAI/.pythonlibs/lib/python3.11/site-packages/playwright/_impl/_connection.py", line 212, in initialize
    await self._channel.send(
  File "/home/runner/SlideCheckAI/.pythonlibs/lib/python3.11/site-packages/playwright/_impl/_connection.py", line 59, in send
    return await self._connection.wrap_api_call(
           ^^^^^^^^^^^^^^^^^^^^^^^^^^^^^^^^^^^^^
  File "/home/runner/SlideCheckAI/.pythonlibs/lib/python3.11/site-packages/playwright/_impl/_connection.py", line 514, in wrap_api_call
    raise rewrite_error(error, f"{parsed_st['apiName']}: {error}") from None
Exception: Connection.init: Connection closed while reading from the driver
DEBUG:urllib3.connectionpool:Starting new HTTPS connection (1): www.canva.com:443
DEBUG:urllib3.connectionpool:https://www.canva.com:443 "GET /templates/EAF4OFZRD4Y-colourful-playful-class-agenda-education-presentation/ HTTP/11" 403 None
Canva processing test passed successfully!
DEBUG:asyncio:Using selector: EpollSelector
/home/runner/SlideCheckAI/.pythonlibs/lib/python3.11/site-packages/playwright/driver/node: /lib/x86_64-linux-gnu/libc.so.6: version `GLIBC_2.38' not found (required by /nix/store/r0lvxcdpachvilzmy1w7pnwxikbvm7az-cpplibs/lib/libstdc++.so.6)
/home/runner/SlideCheckAI/.pythonlibs/lib/python3.11/site-packages/playwright/driver/node: /lib/x86_64-linux-gnu/libc.so.6: version `GLIBC_2.33' not found (required by /nix/store/r0lvxcdpachvilzmy1w7pnwxikbvm7az-cpplibs/lib/libstdc++.so.6)
/home/runner/SlideCheckAI/.pythonlibs/lib/python3.11/site-packages/playwright/driver/node: /lib/x86_64-linux-gnu/libc.so.6: version `GLIBC_2.32' not found (required by /nix/store/r0lvxcdpachvilzmy1w7pnwxikbvm7az-cpplibs/lib/libstdc++.so.6)
/home/runner/SlideCheckAI/.pythonlibs/lib/python3.11/site-packages/playwright/driver/node: /lib/x86_64-linux-gnu/libc.so.6: version `GLIBC_2.36' not found (required by /nix/store/r0lvxcdpachvilzmy1w7pnwxikbvm7az-cpplibs/lib/libstdc++.so.6)
/home/runner/SlideCheckAI/.pythonlibs/lib/python3.11/site-packages/playwright/driver/node: /lib/x86_64-linux-gnu/libc.so.6: version `GLIBC_2.34' not found (required by /nix/store/r0lvxcdpachvilzmy1w7pnwxikbvm7az-cpplibs/lib/libstdc++.so.6)
ERROR:utils.file_processor:Error in Playwright (attempt 1): 'PlaywrightContextManager' object has no attribute '_playwright'
DEBUG:asyncio:Using selector: EpollSelector
/home/runner/SlideCheckAI/.pythonlibs/lib/python3.11/site-packages/playwright/driver/node: /lib/x86_64-linux-gnu/libc.so.6: version `GLIBC_2.38' not found (required by /nix/store/r0lvxcdpachvilzmy1w7pnwxikbvm7az-cpplibs/lib/libstdc++.so.6)
/home/runner/SlideCheckAI/.pythonlibs/lib/python3.11/site-packages/playwright/driver/node: /lib/x86_64-linux-gnu/libc.so.6: version `GLIBC_2.33' not found (required by /nix/store/r0lvxcdpachvilzmy1w7pnwxikbvm7az-cpplibs/lib/libstdc++.so.6)
/home/runner/SlideCheckAI/.pythonlibs/lib/python3.11/site-packages/playwright/driver/node: /lib/x86_64-linux-gnu/libc.so.6: version `GLIBC_2.32' not found (required by /nix/store/r0lvxcdpachvilzmy1w7pnwxikbvm7az-cpplibs/lib/libstdc++.so.6)
/home/runner/SlideCheckAI/.pythonlibs/lib/python3.11/site-packages/playwright/driver/node: /lib/x86_64-linux-gnu/libc.so.6: version `GLIBC_2.36' not found (required by /nix/store/r0lvxcdpachvilzmy1w7pnwxikbvm7az-cpplibs/lib/libstdc++.so.6)
/home/runner/SlideCheckAI/.pythonlibs/lib/python3.11/site-packages/playwright/driver/node: /lib/x86_64-linux-gnu/libc.so.6: version `GLIBC_2.34' not found (required by /nix/store/r0lvxcdpachvilzmy1w7pnwxikbvm7az-cpplibs/lib/libstdc++.so.6)
ERROR:utils.file_processor:Error in Playwright (attempt 2): 'PlaywrightContextManager' object has no attribute '_playwright'
DEBUG:asyncio:Using selector: EpollSelector
/home/runner/SlideCheckAI/.pythonlibs/lib/python3.11/site-packages/playwright/driver/node: /lib/x86_64-linux-gnu/libc.so.6: version `GLIBC_2.38' not found (required by /nix/store/r0lvxcdpachvilzmy1w7pnwxikbvm7az-cpplibs/lib/libstdc++.so.6)
/home/runner/SlideCheckAI/.pythonlibs/lib/python3.11/site-packages/playwright/driver/node: /lib/x86_64-linux-gnu/libc.so.6: version `GLIBC_2.33' not found (required by /nix/store/r0lvxcdpachvilzmy1w7pnwxikbvm7az-cpplibs/lib/libstdc++.so.6)
/home/runner/SlideCheckAI/.pythonlibs/lib/python3.11/site-packages/playwright/driver/node: /lib/x86_64-linux-gnu/libc.so.6: version `GLIBC_2.32' not found (required by /nix/store/r0lvxcdpachvilzmy1w7pnwxikbvm7az-cpplibs/lib/libstdc++.so.6)
/home/runner/SlideCheckAI/.pythonlibs/lib/python3.11/site-packages/playwright/driver/node: /lib/x86_64-linux-gnu/libc.so.6: version `GLIBC_2.36' not found (required by /nix/store/r0lvxcdpachvilzmy1w7pnwxikbvm7az-cpplibs/lib/libstdc++.so.6)
/home/runner/SlideCheckAI/.pythonlibs/lib/python3.11/site-packages/playwright/driver/node: /lib/x86_64-linux-gnu/libc.so.6: version `GLIBC_2.34' not found (required by /nix/store/r0lvxcdpachvilzmy1w7pnwxikbvm7az-cpplibs/lib/libstdc++.so.6)
ERROR:utils.file_processor:Error in Playwright (attempt 3): 'PlaywrightContextManager' object has no attribute '_playwright'
ERROR:utils.file_processor:Error processing Figma link: 'PlaywrightContextManager' object has no attribute '_playwright'
Traceback (most recent call last):
  File "/home/runner/SlideCheckAI/utils/file_processor.py", line 213, in process_figma_link
    with sync_playwright() as p:
  File "/home/runner/SlideCheckAI/.pythonlibs/lib/python3.11/site-packages/playwright/sync_api/_context_manager.py", line 79, in __enter__
    playwright = self._playwright
                 ^^^^^^^^^^^^^^^^
AttributeError: 'PlaywrightContextManager' object has no attribute '_playwright'
DEBUG:urllib3.connectionpool:Starting new HTTPS connection (1): www.figma.com:443
DEBUG:urllib3.connectionpool:https://www.figma.com:443 "GET /deck/MmzfmAWwR06geAJ7geK9MJ/project-status-template?node-id=1-284&node-type=slide&t=DoHGcqXgkDxaeMEB-1&scaling=min-zoom&content-scaling=fixed&page-id=0%3A1 HTTP/11" 200 None
ERROR:asyncio:Task exception was never retrieved
future: <Task finished name='Task-12' coro=<Connection.run.<locals>.init() done, defined at /home/runner/SlideCheckAI/.pythonlibs/lib/python3.11/site-packages/playwright/_impl/_connection.py:269> exception=Exception('Connection.init: Connection closed while reading from the driver')>
Traceback (most recent call last):
  File "/home/runner/SlideCheckAI/.pythonlibs/lib/python3.11/site-packages/playwright/_impl/_connection.py", line 270, in init
    self.playwright_future.set_result(await self._root_object.initialize())
                                      ^^^^^^^^^^^^^^^^^^^^^^^^^^^^^^^^^^^^
  File "/home/runner/SlideCheckAI/.pythonlibs/lib/python3.11/site-packages/playwright/_impl/_connection.py", line 212, in initialize
    await self._channel.send(
  File "/home/runner/SlideCheckAI/.pythonlibs/lib/python3.11/site-packages/playwright/_impl/_connection.py", line 59, in send
    return await self._connection.wrap_api_call(
           ^^^^^^^^^^^^^^^^^^^^^^^^^^^^^^^^^^^^^
  File "/home/runner/SlideCheckAI/.pythonlibs/lib/python3.11/site-packages/playwright/_impl/_connection.py", line 514, in wrap_api_call
    raise rewrite_error(error, f"{parsed_st['apiName']}: {error}") from None
Exception: Connection.init: Connection closed while reading from the driver
ERROR:asyncio:Task exception was never retrieved
future: <Task finished name='Task-15' coro=<Connection.run.<locals>.init() done, defined at /home/runner/SlideCheckAI/.pythonlibs/lib/python3.11/site-packages/playwright/_impl/_connection.py:269> exception=Exception('Connection.init: Connection closed while reading from the driver')>
Traceback (most recent call last):
  File "/home/runner/SlideCheckAI/.pythonlibs/lib/python3.11/site-packages/playwright/_impl/_connection.py", line 270, in init
    self.playwright_future.set_result(await self._root_object.initialize())
                                      ^^^^^^^^^^^^^^^^^^^^^^^^^^^^^^^^^^^^
  File "/home/runner/SlideCheckAI/.pythonlibs/lib/python3.11/site-packages/playwright/_impl/_connection.py", line 212, in initialize
    await self._channel.send(
  File "/home/runner/SlideCheckAI/.pythonlibs/lib/python3.11/site-packages/playwright/_impl/_connection.py", line 59, in send
    return await self._connection.wrap_api_call(
           ^^^^^^^^^^^^^^^^^^^^^^^^^^^^^^^^^^^^^
  File "/home/runner/SlideCheckAI/.pythonlibs/lib/python3.11/site-packages/playwright/_impl/_connection.py", line 514, in wrap_api_call
    raise rewrite_error(error, f"{parsed_st['apiName']}: {error}") from None
Exception: Connection.init: Connection closed while reading from the driver
Figma processing test passed successfully!
Keynote test skipped: No sample file available
ERROR:asyncio:Future exception was never retrieved
future: <Future finished exception=Exception('Connection closed while reading from the driver')>
Exception: Connection closed while reading from the driver
ERROR:asyncio:Task was destroyed but it is pending!
task: <Task pending name='Task-3' coro=<Connection.run.<locals>.init() running at /home/runner/SlideCheckAI/.pythonlibs/lib/python3.11/site-packages/playwright/_impl/_connection.py:270> wait_for=<Future finished result=None> cb=[ProtocolCallback.__init__.<locals>.cb() at /home/runner/SlideCheckAI/.pythonlibs/lib/python3.11/site-packages/playwright/_impl/_connection.py:191]>
ERROR:asyncio:Task exception was never retrieved
future: <Task finished name='Task-9' coro=<Connection.run.<locals>.init() done, defined at /home/runner/SlideCheckAI/.pythonlibs/lib/python3.11/site-packages/playwright/_impl/_connection.py:269> exception=Exception('Connection.init: Connection closed while reading from the driver')>
Traceback (most recent call last):
  File "/home/runner/SlideCheckAI/.pythonlibs/lib/python3.11/site-packages/playwright/_impl/_connection.py", line 270, in init
    self.playwright_future.set_result(await self._root_object.initialize())
                                      ^^^^^^^^^^^^^^^^^^^^^^^^^^^^^^^^^^^^
  File "/home/runner/SlideCheckAI/.pythonlibs/lib/python3.11/site-packages/playwright/_impl/_connection.py", line 212, in initialize
    await self._channel.send(
  File "/home/runner/SlideCheckAI/.pythonlibs/lib/python3.11/site-packages/playwright/_impl/_connection.py", line 59, in send
    return await self._connection.wrap_api_call(
           ^^^^^^^^^^^^^^^^^^^^^^^^^^^^^^^^^^^^^
  File "/home/runner/SlideCheckAI/.pythonlibs/lib/python3.11/site-packages/playwright/_impl/_connection.py", line 514, in wrap_api_call
    raise rewrite_error(error, f"{parsed_st['apiName']}: {error}") from None
Exception: Connection.init: Connection closed while reading from the driver
ERROR:asyncio:Task exception was never retrieved
future: <Task finished name='Task-18' coro=<Connection.run.<locals>.init() done, defined at /home/runner/SlideCheckAI/.pythonlibs/lib/python3.11/site-packages/playwright/_impl/_connection.py:269> exception=Exception('Connection.init: Connection closed while reading from the driver')>
Traceback (most recent call last):
  File "/home/runner/SlideCheckAI/.pythonlibs/lib/python3.11/site-packages/playwright/_impl/_connection.py", line 270, in init
    self.playwright_future.set_result(await self._root_object.initialize())
                                      ^^^^^^^^^^^^^^^^^^^^^^^^^^^^^^^^^^^^
  File "/home/runner/SlideCheckAI/.pythonlibs/lib/python3.11/site-packages/playwright/_impl/_connection.py", line 212, in initialize
    await self._channel.send(
  File "/home/runner/SlideCheckAI/.pythonlibs/lib/python3.11/site-packages/playwright/_impl/_connection.py", line 59, in send
    return await self._connection.wrap_api_call(
           ^^^^^^^^^^^^^^^^^^^^^^^^^^^^^^^^^^^^^
  File "/home/runner/SlideCheckAI/.pythonlibs/lib/python3.11/site-packages/playwright/_impl/_connection.py", line 514, in wrap_api_call
    raise rewrite_error(error, f"{parsed_st['apiName']}: {error}") from None
Exception: Connection.init: Connection closed while reading from the driver
