DEBUG:utils.file_processor:Starting to process input: /tmp/tmpm1rwhmxr.pdf
ERROR:utils.file_processor:Error in process_file: Failed to open file '/tmp/tmpm1rwhmxr.pdf'.
Traceback (most recent call last):
  File "/home/runner/SlideCheckAI/.pythonlibs/lib/python3.11/site-packages/pymupdf/__init__.py", line 2820, in __init__
    doc = mupdf.fz_open_document(filename)
          ^^^^^^^^^^^^^^^^^^^^^^^^^^^^^^^^
  File "/home/runner/SlideCheckAI/.pythonlibs/lib/python3.11/site-packages/pymupdf/mupdf.py", line 44273, in fz_open_document
    return _mupdf.fz_open_document(filename)
           ^^^^^^^^^^^^^^^^^^^^^^^^^^^^^^^^^
pymupdf.mupdf.FzErrorFormat: code=7: no objects found

The above exception was the direct cause of the following exception:

Traceback (most recent call last):
  File "/home/runner/SlideCheckAI/utils/file_processor.py", line 48, in process_file
    result = process_pdf(input_data)
             ^^^^^^^^^^^^^^^^^^^^^^^
  File "/home/runner/SlideCheckAI/utils/file_processor.py", line 77, in process_pdf
    doc = fitz.open(pdf_path)
          ^^^^^^^^^^^^^^^^^^^
  File "/home/runner/SlideCheckAI/.pythonlibs/lib/python3.11/site-packages/pymupdf/__init__.py", line 2823, in __init__
    raise FileDataError(f'Failed to open file {filename!r}.') from e
pymupdf.FileDataError: Failed to open file '/tmp/tmpm1rwhmxr.pdf'.
ERROR:__main__:Error during PDF processing test: 'type'
Traceback (most recent call last):
  File "/home/runner/SlideCheckAI/test_all_formats.py", line 16, in test_pdf
    assert result['type'] == 'pdf', "Result type should be 'pdf'"
           ~~~~~~^^^^^^^^
KeyError: 'type'
PPTX test skipped: No sample file available
OTP test skipped: No sample file available
DEBUG:asyncio:Using selector: EpollSelector
/home/runner/SlideCheckAI/.pythonlibs/lib/python3.11/site-packages/playwright/driver/node: /lib/x86_64-linux-gnu/libc.so.6: version `GLIBC_2.38' not found (required by /nix/store/r0lvxcdpachvilzmy1w7pnwxikbvm7az-cpplibs/lib/libstdc++.so.6)
/home/runner/SlideCheckAI/.pythonlibs/lib/python3.11/site-packages/playwright/driver/node: /lib/x86_64-linux-gnu/libc.so.6: version `GLIBC_2.33' not found (required by /nix/store/r0lvxcdpachvilzmy1w7pnwxikbvm7az-cpplibs/lib/libstdc++.so.6)
/home/runner/SlideCheckAI/.pythonlibs/lib/python3.11/site-packages/playwright/driver/node: /lib/x86_64-linux-gnu/libc.so.6: version `GLIBC_2.32' not found (required by /nix/store/r0lvxcdpachvilzmy1w7pnwxikbvm7az-cpplibs/lib/libstdc++.so.6)
/home/runner/SlideCheckAI/.pythonlibs/lib/python3.11/site-packages/playwright/driver/node: /lib/x86_64-linux-gnu/libc.so.6: version `GLIBC_2.36' not found (required by /nix/store/r0lvxcdpachvilzmy1w7pnwxikbvm7az-cpplibs/lib/libstdc++.so.6)
/home/runner/SlideCheckAI/.pythonlibs/lib/python3.11/site-packages/playwright/driver/node: /lib/x86_64-linux-gnu/libc.so.6: version `GLIBC_2.34' not found (required by /nix/store/r0lvxcdpachvilzmy1w7pnwxikbvm7az-cpplibs/lib/libstdc++.so.6)
ERROR:utils.file_processor:Error initializing Playwright: 'PlaywrightContextManager' object has no attribute '_playwright'
DEBUG:urllib3.connectionpool:Starting new HTTPS connection (1): www.canva.com:443
DEBUG:urllib3.connectionpool:https://www.canva.com:443 "GET /design/DAFxxx/view HTTP/11" 403 None
Canva processing test passed successfully!
DEBUG:asyncio:Using selector: EpollSelector
/home/runner/SlideCheckAI/.pythonlibs/lib/python3.11/site-packages/playwright/driver/node: /lib/x86_64-linux-gnu/libc.so.6: version `GLIBC_2.38' not found (required by /nix/store/r0lvxcdpachvilzmy1w7pnwxikbvm7az-cpplibs/lib/libstdc++.so.6)
/home/runner/SlideCheckAI/.pythonlibs/lib/python3.11/site-packages/playwright/driver/node: /lib/x86_64-linux-gnu/libc.so.6: version `GLIBC_2.33' not found (required by /nix/store/r0lvxcdpachvilzmy1w7pnwxikbvm7az-cpplibs/lib/libstdc++.so.6)
/home/runner/SlideCheckAI/.pythonlibs/lib/python3.11/site-packages/playwright/driver/node: /lib/x86_64-linux-gnu/libc.so.6: version `GLIBC_2.32' not found (required by /nix/store/r0lvxcdpachvilzmy1w7pnwxikbvm7az-cpplibs/lib/libstdc++.so.6)
/home/runner/SlideCheckAI/.pythonlibs/lib/python3.11/site-packages/playwright/driver/node: /lib/x86_64-linux-gnu/libc.so.6: version `GLIBC_2.36' not found (required by /nix/store/r0lvxcdpachvilzmy1w7pnwxikbvm7az-cpplibs/lib/libstdc++.so.6)
/home/runner/SlideCheckAI/.pythonlibs/lib/python3.11/site-packages/playwright/driver/node: /lib/x86_64-linux-gnu/libc.so.6: version `GLIBC_2.34' not found (required by /nix/store/r0lvxcdpachvilzmy1w7pnwxikbvm7az-cpplibs/lib/libstdc++.so.6)
ERROR:utils.file_processor:Error initializing Playwright: 'PlaywrightContextManager' object has no attribute '_playwright'
DEBUG:urllib3.connectionpool:Starting new HTTPS connection (1): www.figma.com:443
DEBUG:urllib3.connectionpool:https://www.figma.com:443 "GET /file/xxx/Sample-Presentation HTTP/11" 403 919
Figma processing test passed successfully!
Keynote test skipped: No sample file available
ERROR:asyncio:Task was destroyed but it is pending!
task: <Task pending name='Task-3' coro=<Connection.run.<locals>.init() running at /home/runner/SlideCheckAI/.pythonlibs/lib/python3.11/site-packages/playwright/_impl/_connection.py:270> wait_for=<Future finished result=None> cb=[ProtocolCallback.__init__.<locals>.cb() at /home/runner/SlideCheckAI/.pythonlibs/lib/python3.11/site-packages/playwright/_impl/_connection.py:191]>
ERROR:asyncio:Future exception was never retrieved
future: <Future finished exception=Exception('Connection closed while reading from the driver')>
Exception: Connection closed while reading from the driver
ERROR:asyncio:Task exception was never retrieved
future: <Task finished name='Task-6' coro=<Connection.run.<locals>.init() done, defined at /home/runner/SlideCheckAI/.pythonlibs/lib/python3.11/site-packages/playwright/_impl/_connection.py:269> exception=Exception('Connection.init: Connection closed while reading from the driver')>
Traceback (most recent call last):
  File "/home/runner/SlideCheckAI/.pythonlibs/lib/python3.11/site-packages/playwright/_impl/_connection.py", line 270, in init
    self.playwright_future.set_result(await self._root_object.initialize())
                                      ^^^^^^^^^^^^^^^^^^^^^^^^^^^^^^^^^^^^
  File "/home/runner/SlideCheckAI/.pythonlibs/lib/python3.11/site-packages/playwright/_impl/_connection.py", line 212, in initialize
    await self._channel.send(
  File "/home/runner/SlideCheckAI/.pythonlibs/lib/python3.11/site-packages/playwright/_impl/_connection.py", line 59, in send
    return await self._connection.wrap_api_call(
           ^^^^^^^^^^^^^^^^^^^^^^^^^^^^^^^^^^^^^
  File "/home/runner/SlideCheckAI/.pythonlibs/lib/python3.11/site-packages/playwright/_impl/_connection.py", line 514, in wrap_api_call
    raise rewrite_error(error, f"{parsed_st['apiName']}: {error}") from None
Exception: Connection.init: Connection closed while reading from the driver
